<?xml version="1.0"?>
<robot name="aloha_wx250s" xmlns:xacro="http://ros.org/wiki/xacro">

  <xacro:property name="robot_model"
    value="aloha_wx250s"
    scope="global"/>
  <xacro:property name="dof"
    value="6"
    scope="global"/>

  <xacro:arg name="robot_name"                      default="${robot_model}"/>
  <xacro:arg name="base_link_frame"                 default="base_link"/>
  <xacro:arg name="use_gripper"                     default="true"/>
  <xacro:arg name="show_ar_tag"                     default="false"/>
  <xacro:arg name="show_handle"                     default="true"/>
  <xacro:arg name="show_gripper_bar"                default="true"/>
  <xacro:arg name="show_gripper_fingers"            default="true"/>
  <xacro:arg name="use_world_frame"                 default="false"/>
  <xacro:arg name="external_urdf_loc"               default=""/>
  <xacro:arg name="hardware_type"                   default="actual"/>

  <xacro:property name="mesh_directory"             value="package://interbotix_xsarm_descriptions/meshes/${robot_model}_meshes"/>
  <xacro:property name="urdf_loc"                   value="$(arg external_urdf_loc)"/>
  <xacro:property name="hardware_type"              value="$(arg hardware_type)"/>
  <xacro:property name="pi_offset"                  value="0.00001"/>

  <xacro:property name="waist_limit_effort"         value="10"/>
  <xacro:property name="waist_limit_lower"          value="${-pi + pi_offset}"/>
  <xacro:property name="waist_limit_upper"          value="${pi - pi_offset}"/>
  <xacro:property name="waist_limit_vel"            value="${pi}"/>

  <xacro:property name="shoulder_limit_effort"      value="20"/>
  <xacro:property name="shoulder_limit_lower"       value="${radians(-108)}"/>
  <xacro:property name="shoulder_limit_upper"       value="${radians(114)}"/>
  <xacro:property name="shoulder_limit_vel"         value="${pi}"/>

  <xacro:property name="elbow_limit_effort"         value="15"/>
  <xacro:property name="elbow_limit_lower"          value="${radians(-123)}"/>
  <xacro:property name="elbow_limit_upper"          value="${radians(92)}"/>
  <xacro:property name="elbow_limit_vel"            value="${pi}"/>

  <xacro:property name="forearm_roll_limit_effort"   value="2"/>
  <xacro:property name="forearm_roll_limit_lower"    value="${-pi + pi_offset}"/>
  <xacro:property name="forearm_roll_limit_upper"    value="${pi - pi_offset}"/>
  <xacro:property name="forearm_roll_limit_vel"      value="${pi}"/>

  <xacro:property name="wrist_angle_limit_effort"   value="5"/>
  <xacro:property name="wrist_angle_limit_lower"    value="${radians(-100)}"/>
  <xacro:property name="wrist_angle_limit_upper"    value="${radians(123)}"/>
  <xacro:property name="wrist_angle_limit_vel"      value="${pi}"/>

  <xacro:property name="wrist_rotate_limit_effort"  value="1"/>
  <xacro:property name="wrist_rotate_limit_lower"   value="${-pi + pi_offset}"/>
  <xacro:property name="wrist_rotate_limit_upper"   value="${pi - pi_offset}"/>
  <xacro:property name="wrist_rotate_limit_vel"     value="${pi}"/>

  <xacro:property name="gripper_limit_vel"          value="${pi}"/>

  <xacro:property name="finger_limit_effort"        value="5"/>
  <xacro:property name="finger_limit_lower"         value="0.015"/>
  <xacro:property name="finger_limit_upper"         value="0.037"/>
  <xacro:property name="finger_limit_vel"           value="1"/>

  <material name="interbotix_black">
    <texture filename="package://interbotix_xsarm_descriptions/meshes/interbotix_black.png"/>
  </material>

  <xacro:if value="$(arg use_world_frame)">
    <link name="world"/>
    <joint name="fixed" type="fixed">
      <parent
        link="world"/>
      <child
        link="$(arg robot_name)/$(arg base_link_frame)"/>
    </joint>
  </xacro:if> <!-- use_world_frame -->

  <link name="$(arg robot_name)/$(arg base_link_frame)">
    <visual>
      <origin
        rpy="0 0 ${pi/2}"
        xyz="0 0 0"/>
      <geometry>
        <mesh
          filename="${mesh_directory}/base.stl"
          scale="0.001 0.001 0.001"/>
      </geometry>
      <material name="interbotix_black"/>
    </visual>
    <collision>
      <origin
        rpy="0 0 ${pi/2}"
        xyz="0 0 0"/>
      <geometry>
        <mesh
          filename="${mesh_directory}/base.stl"
          scale="0.001 0.001 0.001"/>
      </geometry>
    </collision>
    <inertial>
      <origin
        rpy="0 0 ${pi/2}"
        xyz="-0.0380446000 0.0006138920 0.0193354000"/>
      <mass value="0.538736"/>
      <inertia
        ixx="0.0021150000"
        iyy="0.0006921000"
        izz="0.0025240000"
        ixy="-0.0000163500"
        ixz="0.0000006998"
        iyz="0.0000464200"/>
    </inertial>
  </link>

  <joint name="waist" type="revolute">
    <axis xyz="0 0 1"/>
    <limit
      effort="${waist_limit_effort}"
      lower="${waist_limit_lower}"
      upper="${waist_limit_upper}"
      velocity="${waist_limit_vel}"/>
    <origin
      rpy="0 0 0"
      xyz="0 0 0.072"/>
    <parent
      link="$(arg robot_name)/$(arg base_link_frame)"/>
    <child
      link="$(arg robot_name)/shoulder_link"/>
    <dynamics
      friction="0.1"
      damping="0.1"/>
  </joint>

  <link name="$(arg robot_name)/shoulder_link">
    <visual>
      <origin
        rpy="0 0 ${pi/2}"
        xyz="0 0 -0.003"/>
      <geometry>
        <mesh
          filename="${mesh_directory}/shoulder.stl"
          scale="0.001 0.001 0.001"/>
      </geometry>
      <material name="interbotix_black"/>
    </visual>
    <collision>
      <origin
        rpy="0 0 ${pi/2}"
        xyz="0 0 -0.003"/>
      <geometry>
        <mesh
          filename="${mesh_directory}/shoulder.stl"
          scale="0.001 0.001 0.001"/>
      </geometry>
    </collision>
    <inertial>
      <origin
        rpy="0 0 ${pi/2}"
        xyz="0.0000223482 0.0000414609 0.0066287000"/>
      <mass value="0.480879"/>
      <inertia
        ixx="0.0003790000"
        iyy="0.0005557000"
        izz="0.0005889000"
        ixy="0.0000000022"
        ixz="-0.0000003561"
        iyz="0.0000012245"/>
    </inertial>
  </link>

  <joint name="shoulder" type="revolute">
    <axis xyz="0 1 0"/>
    <limit
      effort="${shoulder_limit_effort}"
      lower="${shoulder_limit_lower}"
      upper="${shoulder_limit_upper}"
      velocity="${shoulder_limit_vel}"/>
    <origin
      rpy="0 0 0"
      xyz="0 0 0.03865"/>
    <parent
      link="$(arg robot_name)/shoulder_link"/>
    <child
      link="$(arg robot_name)/upper_arm_link"/>
    <dynamics
      friction="0.1"
      damping="0.1"/>
  </joint>

  <link name="$(arg robot_name)/upper_arm_link">
    <visual>
      <origin
        rpy="0 0 ${pi/2}"
        xyz="0 0 0"/>
      <geometry>
        <mesh
          filename="${mesh_directory}/upper_arm.stl"
          scale="0.001 0.001 0.001"/>
      </geometry>
      <material name="interbotix_black"/>
    </visual>
    <collision>
      <origin
        rpy="0 0 ${pi/2}"
        xyz="0 0 0"/>
      <geometry>
        <mesh
          filename="${mesh_directory}/upper_arm.stl"
          scale="0.001 0.001 0.001"/>
      </geometry>
    </collision>
    <inertial>
      <origin
        rpy="0 0 0"
        xyz="0.0153860000 0.0000000000 0.1851100000"/>
      <mass value="0.4897150000"/>
      <inertia
        ixx="0.0043745412"
        iyy="0.0042527386"
        izz="0.0004827537"
        ixy="0.0000000002"
        ixz="-0.0004799594"
        iyz="-0.0000000015"/>
    </inertial>
  </link>

  <joint name="elbow" type="revolute">
    <axis xyz="0 1 0"/>
    <limit
      effort="${elbow_limit_effort}"
      lower="${elbow_limit_lower}"
      upper="${elbow_limit_upper}"
      velocity="${elbow_limit_vel}"/>
    <origin
      rpy="0 0 0"
      xyz="0.04975 0 0.25"/>
    <parent
      link="$(arg robot_name)/upper_arm_link"/>
    <child
      link="$(arg robot_name)/upper_forearm_link"/>
    <dynamics
      friction="0.1"
      damping="0.1"/>
  </joint>

  <link name="$(arg robot_name)/upper_forearm_link">
    <visual>
      <origin
        rpy="0 0 0"
        xyz="0 0 0"/>
      <geometry>
        <mesh
          filename="${mesh_directory}/upper_forearm.stl"
          scale="0.001 0.001 0.001"/>
      </geometry>
      <material name="interbotix_black"/>
    </visual>
    <collision>
      <origin
        rpy="0 0 0"
        xyz="0 0 0"/>
      <geometry>
        <mesh
          filename="${mesh_directory}/upper_forearm.stl"
          scale="0.001 0.001 0.001"/>
      </geometry>
    </collision>
    <inertial>
      <origin
        rpy="0 0 0"
        xyz="0.1079630000 0.0001158760 0"/>
      <mass value="0.234589"/>
      <inertia
        ixx="0.0000397100"
        iyy="0.0008878000"
        izz="0.0008880000"
        ixy="0.0000023528"
        ixz="0"
        iyz="0"/>
    </inertial>
  </link>

  <joint name="forearm_roll" type="revolute">
    <axis xyz="1 0 0"/>
    <limit
      effort="${forearm_roll_limit_effort}"
      lower="${forearm_roll_limit_lower}"
      upper="${forearm_roll_limit_upper}"
      velocity="${forearm_roll_limit_vel}"/>
    <origin
      rpy="0 0 0"
      xyz="0.175 0 0"/>
    <parent
      link="$(arg robot_name)/upper_forearm_link"/>
    <child
      link="$(arg robot_name)/lower_forearm_link"/>
    <dynamics
      friction="0.1"
      damping="0.1"/>
  </joint>

  <link name="$(arg robot_name)/lower_forearm_link">
    <visual>
      <origin
        rpy="${pi} 0 0"
        xyz="0 0 0"/>
      <geometry>
        <mesh
          filename="${mesh_directory}/lower_forearm.stl"
          scale="0.001 0.001 0.001"/>
      </geometry>
      <material name="interbotix_black"/>
    </visual>
    <collision>
      <origin
        rpy="${pi} 0 0"
        xyz="0 0 0"/>
      <geometry>
        <mesh
          filename="${mesh_directory}/lower_forearm.stl"
          scale="0.001 0.001 0.001"/>
      </geometry>
    </collision>
    <inertial>
      <origin
        rpy="0 0 0"
        xyz="0.0335820000 0.0047260000 0.0000000000"/>
      <mass value="0.2529240000"/>
      <inertia
        ixx="0.0000741889"
        iyy="0.0002100083"
        izz="0.0002256883"
        ixy="0.0000194025"
        ixz="0.0000000000"
        iyz="0.0000000004"/>
    </inertial>
  </link>

  <joint name="wrist_angle" type="revolute">
    <axis xyz="0 1 0"/>
    <limit
      effort="${wrist_angle_limit_effort}"
      lower="${wrist_angle_limit_lower}"
      upper="${wrist_angle_limit_upper}"
      velocity="${wrist_angle_limit_vel}"/>
    <origin
      rpy="0 0 0"
      xyz="0.075 0 0"/>
    <parent
      link="$(arg robot_name)/lower_forearm_link"/>
    <child
      link="$(arg robot_name)/wrist_link"/>
    <dynamics
      friction="0.1"
      damping="0.1"/>
  </joint>

  <link name="$(arg robot_name)/wrist_link">
    <visual>
      <origin
        rpy="0 0 ${pi/2}"
        xyz="0 0 0"/>
      <geometry>
        <mesh
          filename="${mesh_directory}/wrist.stl"
          scale="0.001 0.001 0.001"/>
      </geometry>
      <material name="interbotix_black"/>
    </visual>
    <collision>
      <origin
        rpy="0 0 ${pi/2}"
        xyz="0 0 0"/>
      <geometry>
        <mesh
          filename="${mesh_directory}/wrist.stl"
          scale="0.001 0.001 0.001"/>
      </geometry>
    </collision>
    <inertial>
      <origin
        rpy="0 0 0"
        xyz="0.0484000000 0.0000020000 0.0081230000"/>
      <mass value="0.1560520000"/>
      <inertia
        ixx="0.0000551559"
        iyy="0.0000691991"
        izz="0.0000656414"
        ixy="0.0000000002"
        ixz="0.0000037652"
        iyz="-0.0000000042"/>
    </inertial>
  </link>

  <!-- Include the gripper if used -->

  <xacro:if value="$(arg use_gripper)">

    <joint name="wrist_rotate" type="revolute">
      <axis xyz="1 0 0"/>
      <limit
        effort="${wrist_rotate_limit_effort}"
        lower="${wrist_rotate_limit_lower}"
        upper="${wrist_rotate_limit_upper}"
        velocity="${wrist_rotate_limit_vel}"/>
      <origin
        rpy="0 0 0"
        xyz="0.065 0 0"/>
      <parent
        link="$(arg robot_name)/wrist_link"/>
      <child
        link="$(arg robot_name)/gripper_link"/>
      <dynamics
        friction="0.1"
        damping="0.1"/>
    </joint>

    <link name="$(arg robot_name)/gripper_link">
      <visual>
        <origin
          rpy="0 0 ${pi/2}"
          xyz="-0.02 0 0"/>
        <geometry>
          <mesh
            filename="${mesh_directory}/gripper.stl"
            scale="0.001 0.001 0.001"/>
        </geometry>
        <material name="interbotix_black"/>
      </visual>
      <collision>
        <origin
          rpy="0 0 ${pi/2}"
          xyz="-0.02 0 0"/>
        <geometry>
          <mesh
            filename="${mesh_directory}/gripper.stl"
            scale="0.001 0.001 0.001"/>
        </geometry>
      </collision>
      <inertial>
        <origin
          rpy="0 0 0"
          xyz="0.0194110000 0.0000000000 0.0050100000"/>
        <mass value="0.1030950000"/>
        <inertia
          ixx="0.0000324528"
          iyy="0.0000357525"
          izz="0.0000270800"
          ixy="-0.0000000001"
          ixz="-0.0000023449"
          iyz="0.0000000000"/>
      </inertial>
    </link>

    <!-- If the handle is being used, then add the handle -->

    <xacro:if value="$(arg show_handle)">

      <joint name="gripper_handle" type="fixed">
        <axis xyz="1 0 0"/>
        <origin
          rpy="0 0 0"
          xyz="0 0 0"/>
        <parent
          link="$(arg robot_name)/gripper_link"/>
        <child
          link="$(arg robot_name)/handle_link"/>
      </joint>

      <link name="$(arg robot_name)/handle_link">
        <inertial>
          <origin
            rpy="0 0 0"
            xyz="0.0076300000 0.0000000000 -0.0357390000"/>
          <mass value="0.0622240000"/>
          <inertia
            ixx="0.0001321742"
            iyy="0.0001309199"
            izz="0.0000139779"
            ixy="-0.0000000003"
            ixz="-0.0000199732"
            iyz="-0.0000000001"/>
        </inertial>
      </link>

    </xacro:if> <!-- show_handle -->

    <joint name="ee_arm" type="fixed">
      <axis xyz="1 0 0"/>
      <origin
        rpy="0 0 0"
        xyz="0.043 0 0"/>
      <parent
        link="$(arg robot_name)/gripper_link"/>
      <child
        link="$(arg robot_name)/ee_arm_link"/>
    </joint>

    <link name="$(arg robot_name)/ee_arm_link">
      <inertial>
        <mass value="0.001"/>
        <inertia
          ixx="0.001"
          iyy="0.001"
          izz="0.001"
          ixy="0"
          ixz="0"
          iyz="0"/>
      </inertial>
    </link>

    <joint name="gripper" type="continuous">
      <axis xyz="1 0 0"/>
      <limit
        effort="1"
        velocity="${gripper_limit_vel}"/>
      <origin
        rpy="0 0 0"
        xyz="0.0055 0 0"/>
      <parent
        link="$(arg robot_name)/ee_arm_link"/>
      <child
        link="$(arg robot_name)/gripper_prop_link"/>
      <dynamics
        friction="0.1"
        damping="0.1"/>
    </joint>

    <link name="$(arg robot_name)/gripper_prop_link">
      <visual>
        <origin
          rpy="0 0 ${pi/2}"
          xyz="-0.0685 0 0"/>
        <geometry>
          <mesh
            filename="${mesh_directory}/gripper_prop.stl"
            scale="0.001 0.001 0.001"/>
        </geometry>
        <material name="interbotix_black"/>
      </visual>
      <collision>
        <origin
          rpy="0 0 ${pi/2}"
          xyz="-0.0685 0 0"/>
        <geometry>
          <mesh
            filename="${mesh_directory}/gripper_prop.stl"
            scale="0.001 0.001 0.001"/>
        </geometry>
      </collision>
      <inertial>
        <origin
          rpy="0 0 ${pi/2}"
          xyz="0.0008460000 -0.0000016817 0.0000420000"/>
        <mass value="0.01034"/>
        <inertia
          ixx="0.0000005923"
          iyy="0.0000011156"
          izz="0.0000005743"
          ixy="0.0000000000"
          ixz="0.0000003195"
          iyz="-0.0000000004"/>
      </inertial>
    </link>

    <!-- If the AR tag is being used, then add the AR tag mount -->

    <xacro:if value="$(arg show_ar_tag)">
      <xacro:include filename="$(find interbotix_xsarm_descriptions)/urdf/ar_tag.urdf.xacro"/>
    </xacro:if> <!-- show_ar_tag -->

    <!-- If the gripper bar is being used, then also add the gripper bar -->

    <xacro:if value="$(arg show_gripper_bar)">

      <joint name="gripper_bar" type="fixed">
        <axis xyz="1 0 0"/>
        <origin
          rpy="0 0 0"
          xyz="0 0 0"/>
        <parent
          link="$(arg robot_name)/ee_arm_link"/>
        <child
          link="$(arg robot_name)/gripper_bar_link"/>
      </joint>

      <link name="$(arg robot_name)/gripper_bar_link">
        <visual>
          <origin
            rpy="0 0 ${pi/2}"
            xyz="-0.063 0 0"/>
          <geometry>
            <mesh
              filename="${mesh_directory}/gripper_bar.stl"
              scale="0.001 0.001 0.001"/>
          </geometry>
          <material name="interbotix_black"/>
        </visual>
        <collision>
          <origin
            rpy="0 0 ${pi/2}"
            xyz="-0.063 0 0"/>
          <geometry>
            <mesh
              filename="${mesh_directory}/gripper_bar.stl"
              scale="0.001 0.001 0.001"/>
          </geometry>
        </collision>
        <inertial>
          <origin
            rpy="0 0 0"
            xyz="0.0117450000 0.0000000000 0.0018310000"/>
          <mass value="0.1335040000"/>
          <inertia
            ixx="0.0002705379"
            iyy="0.0000371885"
            izz="0.0002579847"
            ixy="0.0000000015"
            ixz="0.0000026430"
            iyz="0.0000000000"/>
        </inertial>
      </link>

      <joint name="ee_bar" type="fixed">
        <axis xyz="1 0 0"/>
        <origin
          rpy="0 0 0"
          xyz="0.023 0 0"/>
        <parent
          link="$(arg robot_name)/gripper_bar_link"/>
        <child
          link="$(arg robot_name)/fingers_link"/>
      </joint>

      <link name="$(arg robot_name)/fingers_link">
        <inertial>
          <mass value="0.001"/>
          <inertia
            ixx="0.001"
            iyy="0.001"
            izz="0.001"
            ixy="0"
            ixz="0"
            iyz="0"/>
        </inertial>
      </link>

      <!-- If the gripper fingers are being used, add those as well -->

      <xacro:if value="$(arg show_gripper_fingers)">

        <joint name="left_finger" type="prismatic">
          <axis xyz="0 1 0"/>
          <limit
            effort="${finger_limit_effort}"
            lower="${finger_limit_lower}"
            upper="${finger_limit_upper}"
            velocity="${finger_limit_vel}"/>
          <origin
            rpy="0 0 0"
            xyz="0 0 0"/>
          <parent
            link="$(arg robot_name)/fingers_link"/>
          <child
            link="$(arg robot_name)/left_finger_link"/>
          <dynamics
            friction="0.1"
            damping="0.1"/>
        </joint>

        <link name="$(arg robot_name)/left_finger_link">
          <visual>
            <origin
              rpy="${pi} ${pi} 0"
              xyz="0 0.005 0"/>
            <geometry>
              <mesh
                filename="${mesh_directory}/gripper_finger.stl"
                scale="0.001 0.001 0.001"/>
            </geometry>
            <material name="interbotix_black"/>
          </visual>
          <collision>
            <origin
              rpy="${pi} ${pi} 0"
              xyz="0 0.005 0"/>
            <geometry>
              <mesh
                filename="${mesh_directory}/gripper_finger.stl"
                scale="0.001 0.001 0.001"/>
            </geometry>
          </collision>
          <inertial>
            <origin
              rpy="0 0 0"
              xyz="0.0042060000 0.0000000000 -0.0080300000"/>
            <mass value="0.0405260000"/>
            <inertia
              ixx="0.0000164667"
              iyy="0.0000169266"
              izz="0.0000038108"
              ixy="-0.0000006813"
              ixz="0.0000001193"
              iyz="-0.0000001691"/>
          </inertial>
        </link>

        <joint name="right_finger" type="prismatic">
          <axis xyz="0 1 0"/>
          <limit
            effort="${finger_limit_effort}"
            lower="${-finger_limit_upper}"
            upper="${-finger_limit_lower}"
            velocity="${finger_limit_vel}"/>
          <origin
            rpy="0 0 0"
            xyz="0 0 0"/>
          <parent
            link="$(arg robot_name)/fingers_link"/>
          <child
            link="$(arg robot_name)/right_finger_link"/>
          <dynamics
            friction="0.1"
            damping="0.1"/>
          <xacro:if value="${hardware_type != 'gz_classic'}">
            <mimic
              joint="left_finger"
              multiplier="-1"
              offset="0"/>
          </xacro:if>
        </joint>

        <link name="$(arg robot_name)/right_finger_link">
          <visual>
            <origin
              rpy="0 ${pi} 0"
              xyz="0 -0.005 0"/>
            <geometry>
              <mesh
                filename="${mesh_directory}/gripper_finger.stl"
                scale="0.001 0.001 0.001"/>
            </geometry>
            <material name="interbotix_black"/>
          </visual>
          <collision>
            <origin
              rpy="0 ${pi} 0"
              xyz="0 -0.005 0"/>
            <geometry>
              <mesh
                filename="${mesh_directory}/gripper_finger.stl"
                scale="0.001 0.001 0.001"/>
            </geometry>
          </collision>
          <inertial>
            <origin
              rpy="0 0 0"
              xyz="0.0039690000 0.0000000000 -0.0065280000"/>
            <mass value="0.0409950000"/>
            <inertia
              ixx="0.0000175327"
              iyy="0.0000181304"
              izz="0.0000039562"
              ixy="0.0000006840"
              ixz="0.0000005777"
              iyz="-0.0000006879"/>
          </inertial>
        </link>

        <joint name="ee_gripper" type="fixed">
          <axis xyz="1 0 0"/>
          <origin
            rpy="0 0 0"
            xyz="0.027575 0 0"/>
          <parent
            link="$(arg robot_name)/fingers_link"/>
          <child
            link="$(arg robot_name)/ee_gripper_link"/>
        </joint>

        <link name="$(arg robot_name)/ee_gripper_link">
          <inertial>
            <mass value="0.001"/>
            <inertia
              ixx="0.001"
              iyy="0.001"
              izz="0.001"
              ixy="0"
              ixz="0"
              iyz="0"/>
          </inertial>
        </link>

      </xacro:if> <!-- show_gripper_fingers -->

    </xacro:if> <!-- show_gripper_bar -->

  </xacro:if> <!-- use_gripper -->

  <xacro:include filename="$(find interbotix_xsarm_descriptions)/urdf/control.urdf.xacro"/>
  <xacro:include filename="$(find interbotix_xsarm_descriptions)/urdf/gazebo_configs.urdf.xacro"/>

  <xacro:if value="${hardware_type == 'gz_classic'}">
    <xacro:gazebo_configs/>
  </xacro:if>

  <xacro:if value="${urdf_loc != ''}">
    <xacro:include filename="${urdf_loc}"/>
  </xacro:if>

</robot>
