<?xml version="1.0"?>
<robot name="mobile_wx200" xmlns:xacro="http://ros.org/wiki/xacro">

  <xacro:property name="robot_model"
    value="mobile_wx200"
    scope="global"/>
  <xacro:property name="dof"
    value="5"
    scope="global"/>

  <xacro:arg name="robot_name"                      default="${robot_model}"/>
  <xacro:arg name="base_link_frame"                 default="base_link"/>
  <xacro:arg name="use_gripper"                     default="true"/>
  <xacro:arg name="show_ar_tag"                     default="false"/>
  <xacro:arg name="show_gripper_bar"                default="true"/>
  <xacro:arg name="show_gripper_fingers"            default="true"/>
  <xacro:arg name="use_world_frame"                 default="false"/>
  <xacro:arg name="external_urdf_loc"               default=""/>
  <xacro:arg name="hardware_type"                   default="actual"/>

  <xacro:property name="mesh_directory"             value="package://interbotix_xsarm_descriptions/meshes/${robot_model}_meshes"/>
  <xacro:property name="urdf_loc"                   value="$(arg external_urdf_loc)"/>
  <xacro:property name="hardware_type"              value="$(arg hardware_type)"/>
  <xacro:property name="pi_offset"                  value="0.00001"/>

  <xacro:property name="waist_limit_effort"         value="8"/>
  <xacro:property name="waist_limit_lower"          value="${-pi + pi_offset}"/>
  <xacro:property name="waist_limit_upper"          value="${pi - pi_offset}"/>
  <xacro:property name="waist_limit_vel"            value="${pi}"/>

  <xacro:property name="shoulder_limit_effort"      value="18"/>
  <xacro:property name="shoulder_limit_lower"       value="${radians(-108)}"/>
  <xacro:property name="shoulder_limit_upper"       value="${radians(113)}"/>
  <xacro:property name="shoulder_limit_vel"         value="${pi}"/>

  <xacro:property name="elbow_limit_effort"         value="13"/>
  <xacro:property name="elbow_limit_lower"          value="${radians(-108)}"/>
  <xacro:property name="elbow_limit_upper"          value="${radians(93)}"/>
  <xacro:property name="elbow_limit_vel"            value="${pi}"/>

  <xacro:property name="wrist_angle_limit_effort"   value="5"/>
  <xacro:property name="wrist_angle_limit_lower"    value="${radians(-100)}"/>
  <xacro:property name="wrist_angle_limit_upper"    value="${radians(123)}"/>
  <xacro:property name="wrist_angle_limit_vel"      value="${pi}"/>

  <xacro:property name="wrist_rotate_limit_effort"  value="1"/>
  <xacro:property name="wrist_rotate_limit_lower"   value="${-pi + pi_offset}"/>
  <xacro:property name="wrist_rotate_limit_upper"   value="${pi - pi_offset}"/>
  <xacro:property name="wrist_rotate_limit_vel"     value="${pi}"/>

  <xacro:property name="gripper_limit_vel"          value="${pi}"/>

  <xacro:property name="finger_limit_effort"        value="5"/>
  <xacro:property name="finger_limit_lower"         value="0.015"/>
  <xacro:property name="finger_limit_upper"         value="0.037"/>
  <xacro:property name="finger_limit_vel"           value="1"/>

  <material name="interbotix_black">
    <texture filename="package://interbotix_xsarm_descriptions/meshes/interbotix_black.png"/>
  </material>

  <xacro:if value="$(arg use_world_frame)">
    <link name="world"/>
    <joint name="fixed" type="fixed">
      <parent
        link="world"/>
      <child
        link="$(arg robot_name)/$(arg base_link_frame)"/>
    </joint>
  </xacro:if> <!-- use_world_frame -->

  <link name="$(arg robot_name)/$(arg base_link_frame)">
    <visual>
      <origin
        rpy="${pi/2} 0 ${pi/2}"
        xyz="-0.095773 0 -0.10565023"/>
      <geometry>
        <mesh
          filename="${mesh_directory}/base.stl"
          scale="0.001 0.001 0.001"/>
      </geometry>
      <material name="interbotix_black"/>
    </visual>
    <collision>
      <origin
        rpy="${pi/2} 0 ${pi/2}"
        xyz="-0.095773 0 -0.10565023"/>
      <geometry>
        <mesh
          filename="${mesh_directory}/base.stl"
          scale="0.001 0.001 0.001"/>
      </geometry>
    </collision>
    <inertial>
      <origin
        rpy="${pi/2} 0 ${pi/2}"
        xyz="-0.0001350000 -0.0000266286 0.0338755000"/>
      <mass value="0.379673"/>
      <inertia
        ixx="0.0004351000"
        iyy="0.0004452000"
        izz="0.0005731000"
        ixy="0.0000000707"
        ixz="0.0000000266"
        iyz="-0.0000022881"/>
    </inertial>
  </link>

  <joint name="waist" type="revolute">
    <axis xyz="0 0 1"/>
    <limit
      effort="${waist_limit_effort}"
      lower="${waist_limit_lower}"
      upper="${waist_limit_upper}"
      velocity="${waist_limit_vel}"/>
    <origin
      rpy="0 0 0"
      xyz="0 0 0.066175"/>
    <parent
      link="$(arg robot_name)/$(arg base_link_frame)"/>
    <child
      link="$(arg robot_name)/shoulder_link"/>
    <dynamics
      friction="0.1"
      damping="0.1"/>
  </joint>

  <link name="$(arg robot_name)/shoulder_link">
    <visual>
      <origin
        rpy="0 0 ${pi/2}"
        xyz="0 0 -0.003"/>
      <geometry>
        <mesh
          filename="${mesh_directory}/shoulder.stl"
          scale="0.001 0.001 0.001"/>
      </geometry>
      <material name="interbotix_black"/>
    </visual>
    <collision>
      <origin
        rpy="0 0 ${pi/2}"
        xyz="0 0 -0.003"/>
      <geometry>
        <mesh
          filename="${mesh_directory}/shoulder.stl"
          scale="0.001 0.001 0.001"/>
      </geometry>
    </collision>
    <inertial>
      <origin
        rpy="0 0 ${pi/2}"
        xyz="0.0000223210 0.0000414608 0.0066287000"/>
      <mass value="0.480879"/>
      <inertia
        ixx="0.0003790000"
        iyy="0.0005557000"
        izz="0.0005889000"
        ixy="0.0000000022"
        ixz="-0.0000003561"
        iyz="0.0000012247"/>
    </inertial>
  </link>

  <joint name="shoulder" type="revolute">
    <axis xyz="0 1 0"/>
    <limit
      effort="${shoulder_limit_effort}"
      lower="${shoulder_limit_lower}"
      upper="${shoulder_limit_upper}"
      velocity="${shoulder_limit_vel}"/>
    <origin
      rpy="0 0 0"
      xyz="0 0 0.03865"/>
    <parent
      link="$(arg robot_name)/shoulder_link"/>
    <child
      link="$(arg robot_name)/upper_arm_link"/>
    <dynamics
      friction="0.1"
      damping="0.1"/>
  </joint>

  <link name="$(arg robot_name)/upper_arm_link">
    <visual>
      <origin
        rpy="0 0 ${pi/2}"
        xyz="0 0 0"/>
      <geometry>
        <mesh
          filename="${mesh_directory}/upper_arm.stl"
          scale="0.001 0.001 0.001"/>
      </geometry>
      <material name="interbotix_black"/>
    </visual>
    <collision>
      <origin
        rpy="0 0 ${pi/2}"
        xyz="0 0 0"/>
      <geometry>
        <mesh
          filename="${mesh_directory}/upper_arm.stl"
          scale="0.001 0.001 0.001"/>
      </geometry>
    </collision>
    <inertial>
      <origin
        rpy="0 0 ${pi/2}"
        xyz="0.0119707000 -0.0001179264 0.1394290000"/>
      <mass value="0.297781"/>
      <inertia
        ixx="0.0017100000"
        iyy="0.0016310000"
        izz="0.0001482000"
        ixy="-0.0000011433"
        ixz="0.0000021161"
        iyz="0.0002135000"/>
    </inertial>
  </link>

  <joint name="elbow" type="revolute">
    <axis xyz="0 1 0"/>
    <limit
      effort="${elbow_limit_effort}"
      lower="${elbow_limit_lower}"
      upper="${elbow_limit_upper}"
      velocity="${elbow_limit_vel}"/>
    <origin
      rpy="0 0 0"
      xyz="0.05 0 0.2"/>
    <parent
      link="$(arg robot_name)/upper_arm_link"/>
    <child
      link="$(arg robot_name)/forearm_link"/>
    <dynamics
      friction="0.1"
      damping="0.1"/>
  </joint>

  <link name="$(arg robot_name)/forearm_link">
    <visual>
      <origin
        rpy="0 0 ${pi/2}"
        xyz="0 0 0"/>
      <geometry>
        <mesh
          filename="${mesh_directory}/forearm.stl"
          scale="0.001 0.001 0.001"/>
      </geometry>
      <material name="interbotix_black"/>
    </visual>
    <collision>
      <origin
        rpy="0 0 ${pi/2}"
        xyz="0 0 0"/>
      <geometry>
        <mesh
          filename="${mesh_directory}/forearm.stl"
          scale="0.001 0.001 0.001"/>
      </geometry>
    </collision>
    <inertial>
      <origin
        rpy="0 0 ${pi/2}"
        xyz="0.1211920000 -0.0001238123 0.0000000000"/>
      <mass value="0.283651"/>
      <inertia
        ixx="0.0011850000"
        iyy="0.0000682900"
        izz="0.0012060000"
        ixy="-0.0000024317"
        ixz="0.0000000000"
        iyz="0.0000000000"/>
    </inertial>
  </link>

  <joint name="wrist_angle" type="revolute">
    <axis xyz="0 1 0"/>
    <limit
      effort="${wrist_angle_limit_effort}"
      lower="${wrist_angle_limit_lower}"
      upper="${wrist_angle_limit_upper}"
      velocity="${wrist_angle_limit_vel}"/>
    <origin
      rpy="0 0 0"
      xyz="0.2 0 0"/>
    <parent
      link="$(arg robot_name)/forearm_link"/>
    <child
      link="$(arg robot_name)/wrist_link"/>
    <dynamics
      friction="0.1"
      damping="0.1"/>
  </joint>

  <link name="$(arg robot_name)/wrist_link">
    <visual>
      <origin
        rpy="0 0 ${pi/2}"
        xyz="0 0 0"/>
      <geometry>
        <mesh
          filename="${mesh_directory}/wrist.stl"
          scale="0.001 0.001 0.001"/>
      </geometry>
      <material name="interbotix_black"/>
    </visual>
    <collision>
      <origin
        rpy="0 0 ${pi/2}"
        xyz="0 0 0"/>
      <geometry>
        <mesh
          filename="${mesh_directory}/wrist.stl"
          scale="0.001 0.001 0.001"/>
      </geometry>
    </collision>
    <inertial>
      <origin
        rpy="0 0 ${pi/2}"
        xyz="0.0423600000 -0.0000106630 0.0105770000"/>
      <mass value="0.084957"/>
      <inertia
        ixx="0.0000308200"
        iyy="0.0000282200"
        izz="0.0000315200"
        ixy="0.0000000191"
        ixz="0.0000000023"
        iyz="0.0000025481"/>
    </inertial>
  </link>

  <!-- Include the gripper if used -->

  <xacro:if value="$(arg use_gripper)">

    <joint name="wrist_rotate" type="revolute">
      <axis xyz="1 0 0"/>
      <limit
        effort="${wrist_rotate_limit_effort}"
        lower="${wrist_rotate_limit_lower}"
        upper="${wrist_rotate_limit_upper}"
        velocity="${wrist_rotate_limit_vel}"/>
      <origin
        rpy="0 0 0"
        xyz="0.065 0 0"/>
      <parent
        link="$(arg robot_name)/wrist_link"/>
      <child
        link="$(arg robot_name)/gripper_link"/>
      <dynamics
        friction="0.1"
        damping="0.1"/>
    </joint>

    <link name="$(arg robot_name)/gripper_link">
      <visual>
        <origin
          rpy="0 0 ${pi/2}"
          xyz="-0.02 0 0"/>
        <geometry>
          <mesh
            filename="${mesh_directory}/gripper.stl"
            scale="0.001 0.001 0.001"/>
        </geometry>
        <material name="interbotix_black"/>
      </visual>
      <collision>
        <origin
          rpy="0 0 ${pi/2}"
          xyz="-0.02 0 0"/>
        <geometry>
          <mesh
            filename="${mesh_directory}/gripper.stl"
            scale="0.001 0.001 0.001"/>
        </geometry>
      </collision>
      <inertial>
        <origin
          rpy="0 0 ${pi/2}"
          xyz="0.0216310000 0.0000002516 0.0114100000"/>
        <mass value="0.072885"/>
        <inertia
          ixx="0.0000253700"
          iyy="0.0000183600"
          izz="0.0000167400"
          ixy="0.0000000000"
          ixz="0.0000000000"
          iyz="0.0000004340"/>
      </inertial>
    </link>

    <joint name="ee_arm" type="fixed">
      <axis xyz="1 0 0"/>
      <origin
        rpy="0 0 0"
        xyz="0.043 0 0"/>
      <parent
        link="$(arg robot_name)/gripper_link"/>
      <child
        link="$(arg robot_name)/ee_arm_link"/>
    </joint>

    <link name="$(arg robot_name)/ee_arm_link">
      <inertial>
        <mass value="0.001"/>
        <inertia
          ixx="0.001"
          iyy="0.001"
          izz="0.001"
          ixy="0"
          ixz="0"
          iyz="0"/>
      </inertial>
    </link>

    <joint name="gripper" type="continuous">
      <axis xyz="1 0 0"/>
      <limit
        effort="1"
        velocity="${gripper_limit_vel}"/>
      <origin
        rpy="0 0 0"
        xyz="0.0055 0 0"/>
      <parent
        link="$(arg robot_name)/ee_arm_link"/>
      <child
        link="$(arg robot_name)/gripper_prop_link"/>
      <dynamics
        friction="0.1"
        damping="0.1"/>
    </joint>

    <link name="$(arg robot_name)/gripper_prop_link">
      <visual>
        <origin
          rpy="0 0 ${pi/2}"
          xyz="-0.0685 0 0"/>
        <geometry>
          <mesh
            filename="${mesh_directory}/gripper_prop.stl"
            scale="0.001 0.001 0.001"/>
        </geometry>
        <material name="interbotix_black"/>
      </visual>
      <collision>
        <origin
          rpy="0 0 ${pi/2}"
          xyz="-0.0685 0 0"/>
        <geometry>
          <mesh
            filename="${mesh_directory}/gripper_prop.stl"
            scale="0.001 0.001 0.001"/>
        </geometry>
      </collision>
      <inertial>
        <origin
          rpy="0 0 ${pi/2}"
          xyz="0.0008460000 -0.0000016817 0.0000420000"/>
        <mass value="0.00434"/>
        <inertia
          ixx="0.0000005923"
          iyy="0.0000011156"
          izz="0.0000005743"
          ixy="0.0000000000"
          ixz="0.0000003195"
          iyz="-0.0000000004"/>
      </inertial>
    </link>

    <!-- If the AR tag is being used, then add the AR tag mount -->

    <xacro:if value="$(arg show_ar_tag)">
      <xacro:include filename="$(find interbotix_xsarm_descriptions)/urdf/ar_tag.urdf.xacro"/>
    </xacro:if> <!-- show_ar_tag -->

    <!-- If the gripper bar is being used, then also add the gripper bar -->

    <xacro:if value="$(arg show_gripper_bar)">

      <joint name="gripper_bar" type="fixed">
        <axis xyz="1 0 0"/>
        <origin
          rpy="0 0 0"
          xyz="0 0 0"/>
        <parent
          link="$(arg robot_name)/ee_arm_link"/>
        <child
          link="$(arg robot_name)/gripper_bar_link"/>
      </joint>

      <link name="$(arg robot_name)/gripper_bar_link">
        <visual>
          <origin
            rpy="0 0 ${pi/2}"
            xyz="-0.063 0 0"/>
          <geometry>
            <mesh
              filename="${mesh_directory}/gripper_bar.stl"
              scale="0.001 0.001 0.001"/>
          </geometry>
          <material name="interbotix_black"/>
        </visual>
        <collision>
          <origin
            rpy="0 0 ${pi/2}"
            xyz="-0.063 0 0"/>
          <geometry>
            <mesh
              filename="${mesh_directory}/gripper_bar.stl"
              scale="0.001 0.001 0.001"/>
          </geometry>
        </collision>
        <inertial>
          <origin
            rpy="0 0 ${pi/2}"
            xyz="0.0096870000 0.0000008177 0.0049620000"/>
          <mass value="0.034199"/>
          <inertia
            ixx="0.0000074125"
            iyy="0.0000284300"
            izz="0.0000286000"
            ixy="-0.0000000008"
            ixz="-0.0000000006"
            iyz="-0.0000013889"/>
        </inertial>
      </link>

      <joint name="ee_bar" type="fixed">
        <axis xyz="1 0 0"/>
        <origin
          rpy="0 0 0"
          xyz="0.023 0 0"/>
        <parent
          link="$(arg robot_name)/gripper_bar_link"/>
        <child
          link="$(arg robot_name)/fingers_link"/>
      </joint>

      <link name="$(arg robot_name)/fingers_link">
        <inertial>
          <mass value="0.001"/>
          <inertia
            ixx="0.001"
            iyy="0.001"
            izz="0.001"
            ixy="0"
            ixz="0"
            iyz="0"/>
        </inertial>
      </link>

      <!-- If the gripper fingers are being used, add those as well -->

      <xacro:if value="$(arg show_gripper_fingers)">

        <joint name="left_finger" type="prismatic">
          <axis xyz="0 1 0"/>
          <limit
            effort="${finger_limit_effort}"
            lower="${finger_limit_lower}"
            upper="${finger_limit_upper}"
            velocity="${finger_limit_vel}"/>
          <origin
            rpy="0 0 0"
            xyz="0 0 0"/>
          <parent
            link="$(arg robot_name)/fingers_link"/>
          <child
            link="$(arg robot_name)/left_finger_link"/>
          <dynamics
            friction="0.1"
            damping="0.1"/>
        </joint>

        <link name="$(arg robot_name)/left_finger_link">
          <visual>
            <origin
              rpy="${pi} ${pi} 0"
              xyz="0 0.005 0"/>
            <geometry>
              <mesh
                filename="${mesh_directory}/gripper_finger.stl"
                scale="0.001 0.001 0.001"/>
            </geometry>
            <material name="interbotix_black"/>
          </visual>
          <collision>
            <origin
              rpy="${pi} ${pi} 0"
              xyz="0 0.005 0"/>
            <geometry>
              <mesh
                filename="${mesh_directory}/gripper_finger.stl"
                scale="0.001 0.001 0.001"/>
            </geometry>
          </collision>
          <inertial>
            <origin
              rpy="${pi} ${pi} ${pi/2}"
              xyz="0.0138160000 0.0000000000 0.0000000000"/>
            <mass value="0.016246"/>
            <inertia
              ixx="0.0000047310"
              iyy="0.0000015506"
              izz="0.0000037467"
              ixy="-0.0000004560"
              ixz="0.0000000000"
              iyz="0.0000000000"/>
          </inertial>
        </link>

        <joint name="right_finger" type="prismatic">
          <axis xyz="0 1 0"/>
          <limit
            effort="${finger_limit_effort}"
            lower="${-finger_limit_upper}"
            upper="${-finger_limit_lower}"
            velocity="${finger_limit_vel}"/>
          <origin
            rpy="0 0 0"
            xyz="0 0 0"/>
          <parent
            link="$(arg robot_name)/fingers_link"/>
          <child
            link="$(arg robot_name)/right_finger_link"/>
          <dynamics
            friction="0.1"
            damping="0.1"/>
          <xacro:if value="${hardware_type != 'gz_classic'}">
            <mimic
              joint="left_finger"
              multiplier="-1"
              offset="0"/>
          </xacro:if>
        </joint>

        <link name="$(arg robot_name)/right_finger_link">
          <visual>
            <origin
              rpy="0 ${pi} 0"
              xyz="0 -0.005 0"/>
            <geometry>
              <mesh
                filename="${mesh_directory}/gripper_finger.stl"
                scale="0.001 0.001 0.001"/>
            </geometry>
            <material name="interbotix_black"/>
          </visual>
          <collision>
            <origin
              rpy="0 ${pi} 0"
              xyz="0 -0.005 0"/>
            <geometry>
              <mesh
                filename="${mesh_directory}/gripper_finger.stl"
                scale="0.001 0.001 0.001"/>
            </geometry>
          </collision>
          <inertial>
            <origin
              rpy="0 ${pi} ${pi/2}"
              xyz="0.0138160000 0.0000000000  0.0000000000"/>
            <mass value="0.016246"/>
            <inertia
              ixx="0.0000047310"
              iyy="0.0000015506"
              izz="0.0000037467"
              ixy="0.0000004560"
              ixz="0.0000000000"
              iyz="0.0000000000"/>
          </inertial>
        </link>

        <joint name="ee_gripper" type="fixed">
          <axis xyz="1 0 0"/>
          <origin
            rpy="0 0 0"
            xyz="0.027575 0 0"/>
          <parent
            link="$(arg robot_name)/fingers_link"/>
          <child
            link="$(arg robot_name)/ee_gripper_link"/>
        </joint>

        <link name="$(arg robot_name)/ee_gripper_link">
          <inertial>
            <mass value="0.001"/>
            <inertia
              ixx="0.001"
              iyy="0.001"
              izz="0.001"
              ixy="0"
              ixz="0"
              iyz="0"/>
          </inertial>
        </link>

      </xacro:if> <!-- show_gripper_fingers -->

    </xacro:if> <!-- show_gripper_bar -->

  </xacro:if> <!-- use_gripper -->

  <xacro:include filename="$(find interbotix_xsarm_descriptions)/urdf/control.urdf.xacro"/>
  <xacro:include filename="$(find interbotix_xsarm_descriptions)/urdf/gazebo_configs.urdf.xacro"/>

  <xacro:if value="${hardware_type == 'gz_classic'}">
    <xacro:gazebo_configs/>
  </xacro:if>

  <xacro:if value="${urdf_loc != ''}">
    <xacro:include filename="${urdf_loc}"/>
  </xacro:if>

</robot>
