<?xml version="1.0"?>
<robot name="uxarm5" xmlns:xacro="http://ros.org/wiki/xacro">

  <xacro:arg name="robot_name" default = "uxarm5"/>
  <xacro:arg name="base_link_frame" default="base_link"/>
  <xacro:arg name="show_gripper" default="true"/>
  <xacro:arg name="use_world_frame" default="false"/>
  <xacro:arg name="external_urdf_loc" default=""/>
  <xacro:arg name="load_gazebo_configs" default="false"/>

  <xacro:property name="urdf_loc" value="$(arg external_urdf_loc)"/>
  <xacro:property name="pi_offset" value="0.00001"/>
  <xacro:property name="gripper_frame" value="$(arg robot_name)/link5"/>

  <xacro:if value="$(arg load_gazebo_configs)">
    <xacro:include filename="$(find interbotix_uxarm_gazebo)/config/uxarm_configs.gazebo"/>
    <xacro:if value="$(arg show_gripper)">
      <xacro:include filename="$(find interbotix_uxarm_gazebo)/config/uxarm_gripper_configs.gazebo"/>
    </xacro:if>
  </xacro:if>

  <material name="White">
    <color rgba="1.0 1.0 1.0 1.0"/>
  </material>

  <material name="Silver">
    <color rgba="0.753 0.753 0.753 1.0"/>
  </material>

  <xacro:if value="$(arg use_world_frame)">
    <link name="world"/>
    <joint name="fixed" type="fixed">
      <parent link="world"/>
      <child link="$(arg robot_name)/$(arg base_link_frame)"/>
    </joint>
  </xacro:if>

  <link name="$(arg robot_name)/$(arg base_link_frame)">
    <visual>
      <origin xyz="0 0 0" rpy="0 0 0"/>
      <geometry>
        <mesh filename="package://interbotix_uxarm_descriptions/meshes/uxarm5_meshes/uxarm5_base.STL"/>
      </geometry>
      <material name="White" />
    </visual>
    <collision>
      <origin xyz="0 0 0" rpy="0 0 0"/>
      <geometry>
        <mesh filename="package://interbotix_uxarm_descriptions/meshes/uxarm5_meshes/uxarm5_base.STL"/>
      </geometry>
    </collision>
    <inertial>
      <origin xyz="-0.00218 -0.00023 0.08604" rpy="0 0 0" />
      <mass value="1.95" />
      <inertia ixx="0.004805" ixy="-8.33E-06" ixz="0.00026847" iyy="0.0050349" iyz="7.23E-06" izz="0.0025418" />
    </inertial>
  </link>

  <joint name="joint1" type="revolute">
    <axis xyz="0 0 1"/>
    <limit effort="100.0" lower="${-pi + pi_offset}" upper="${pi - pi_offset}" velocity="${pi}"/>
    <parent link="$(arg robot_name)/$(arg base_link_frame)"/>
    <child  link="$(arg robot_name)/link1"/>
    <origin xyz="0 0 0.267" rpy="0 0 0"/>
    <dynamics friction="0.5"/>
  </joint>

  <transmission name="tran1">
    <type>transmission_interface/SimpleTransmission</type>
    <joint name="joint1">
      <hardwareInterface>hardware_interface/EffortJointInterface</hardwareInterface>
    </joint>
    <actuator name="motor1">
      <mechanicalReduction>100</mechanicalReduction>
    </actuator>
  </transmission>

  <link name="$(arg robot_name)/link1">
    <visual>
      <origin xyz="0 0 0" rpy="0 0 0"/>
      <geometry>
        <mesh filename="package://interbotix_uxarm_descriptions/meshes/uxarm5_meshes/uxarm5_link1.STL"/>
      </geometry>
      <material name="White"/>
    </visual>
    <collision>
      <origin xyz="0 0 0" rpy="0 0 0"/>
      <geometry>
        <mesh filename="package://interbotix_uxarm_descriptions/meshes/uxarm5_meshes/uxarm5_link1.STL"/>
      </geometry>
    </collision>
    <inertial>
      <origin xyz="0.00016 0.02064 -0.01556" rpy="0 0 0"/>
      <mass value="1.85" />
      <inertia ixx="0.0046885" ixy="-8.67E-06" ixz="2.439E-05" iyy="0.0041688" iyz="0.0006114" izz="0.0024758"/>
    </inertial>
  </link>

  <joint name="joint2" type="revolute">
    <axis xyz="0 0 1"/>
    <parent link="$(arg robot_name)/link1"/>
    <child link="$(arg robot_name)/link2"/>
    <origin xyz="0 0 0" rpy="-1.5708 0 0" />
    <limit effort="100.0" lower="-2.059" upper="2.0944" velocity="${pi}"/>
    <dynamics friction="0.5"/>
  </joint>

  <transmission name="tran2">
    <type>transmission_interface/SimpleTransmission</type>
    <joint name="joint2">
      <hardwareInterface>hardware_interface/EffortJointInterface</hardwareInterface>
    </joint>
    <actuator name="motor2">
      <mechanicalReduction>100</mechanicalReduction>
    </actuator>
  </transmission>

  <link name="$(arg robot_name)/link2">
    <visual>
      <origin xyz="0 0 0" rpy="0 0 0"/>
      <geometry>
        <mesh filename="package://interbotix_uxarm_descriptions/meshes/uxarm5_meshes/uxarm5_link2.STL"/>
      </geometry>
      <material name="White"/>
    </visual>
    <collision>
      <origin xyz="0 0 0" rpy="0 0 0"/>
      <geometry>
        <mesh filename="package://interbotix_uxarm_descriptions/meshes/uxarm5_meshes/uxarm5_link2.STL"/>
      </geometry>
    </collision>
    <inertial>
      <origin xyz="0.0351 -0.21375 0.02835" rpy="0 0 0" />
      <mass value="1.71" />
      <inertia ixx="0.024904" ixy="-0.004271" ixz="-0.0008356" iyy="0.004901" iyz="0.0052393" izz="0.0238188"/>
    </inertial>
  </link>

  <joint name="joint3" type="revolute">
    <axis xyz="0 0 1"/>
    <parent link="$(arg robot_name)/link2"/>
    <child link="$(arg robot_name)/link3"/>
    <origin xyz="0.0535 -0.2845 0" rpy="0 0 0" />
    <limit effort="100.0" lower="-3.927" upper="0.19198" velocity="${pi}"/>
    <dynamics friction="0.5"/>
  </joint>

  <transmission name="tran3">
    <type>transmission_interface/SimpleTransmission</type>
    <joint name="joint3">
      <hardwareInterface>hardware_interface/EffortJointInterface</hardwareInterface>
    </joint>
    <actuator name="motor3">
      <mechanicalReduction>100</mechanicalReduction>
    </actuator>
  </transmission>

  <link name="$(arg robot_name)/link3">
    <visual>
      <origin xyz="0 0 0" rpy="0 0 0"/>
      <geometry>
        <mesh filename="package://interbotix_uxarm_descriptions/meshes/uxarm5_meshes/uxarm5_link3.STL"/>
      </geometry>
      <material name="White"/>
    </visual>
    <collision>
      <origin xyz="0 0 0" rpy="0 0 0"/>
      <geometry>
        <mesh filename="package://interbotix_uxarm_descriptions/meshes/uxarm5_meshes/uxarm5_link3.STL"/>
      </geometry>
    </collision>
    <inertial>
      <origin xyz="0.06716 0.2299 -0.00249" rpy="0 0 0" />
      <mass value="1.74" />
      <inertia ixx="0.0335922" ixy="0.0040788" ixz="-0.0014658" iyy="0.0055857" iyz="-0.0080609" izz="0.0318905"/>
    </inertial>
  </link>

  <joint name="joint4" type="revolute">
    <axis xyz="0 0 1"/>
    <parent link="$(arg robot_name)/link3"/>
    <child link="$(arg robot_name)/link4"/>
    <origin xyz="0.0775 0.3425 0" rpy="0 0 0"/>
    <limit effort="100.0" lower="-1.69297" upper="${pi}" velocity="${pi}"/>
    <dynamics friction="0.5"/>
  </joint>

  <transmission name="tran4">
    <type>transmission_interface/SimpleTransmission</type>
    <joint name="joint4">
      <hardwareInterface>hardware_interface/EffortJointInterface</hardwareInterface>
    </joint>
    <actuator name="motor4">
      <mechanicalReduction>100</mechanicalReduction>
    </actuator>
  </transmission>

  <link name="$(arg robot_name)/link4">
    <visual>
      <origin xyz="0 0 0" rpy="0 0 0"/>
      <geometry>
        <mesh filename="package://interbotix_uxarm_descriptions/meshes/uxarm5_meshes/uxarm5_link4.STL"/>
      </geometry>
      <material name="White"/>
    </visual>
    <collision>
      <origin xyz="0 0 0" rpy="0 0 0"/>
      <geometry>
        <mesh filename="package://interbotix_uxarm_descriptions/meshes/uxarm5_meshes/uxarm5_link4.STL"/>
      </geometry>
    </collision>
    <inertial>
      <origin xyz="0.0636 0.02203 0.00355" rpy="0 0 0" />
      <mass value="1.13" />
      <inertia ixx="0.0010927" ixy="0.0003076" ixz="-0.0002076" iyy="0.0016058" iyz="-8.863E-05" izz="0.0019148"/>
    </inertial>
  </link>

  <joint name="joint5" type="revolute">
    <axis xyz="0 0 1"/>
    <parent link="$(arg robot_name)/link4"/>
    <child link="$(arg robot_name)/link5"/>
    <origin xyz="0.076 0.097 0" rpy="-1.5708 0 0"/>
    <limit effort="100.0" lower="${-pi + pi_offset}" upper="${pi - pi_offset}" velocity="${pi}"/>
    <dynamics friction="0.5"/>
  </joint>

  <transmission name="tran5">
    <type>transmission_interface/SimpleTransmission</type>
    <joint name="joint5">
      <hardwareInterface>hardware_interface/EffortJointInterface</hardwareInterface>
    </joint>
    <actuator name="motor5">
      <mechanicalReduction>100</mechanicalReduction>
    </actuator>
  </transmission>

  <link name="$(arg robot_name)/link5">
    <visual>
      <origin xyz="0 0 0" rpy="0 0 0"/>
      <geometry>
        <mesh filename="package://interbotix_uxarm_descriptions/meshes/uxarm5_meshes/uxarm5_link5.STL"/>
      </geometry>
      <material name="White"/>
    </visual>
    <collision>
      <origin xyz="0 0 0" rpy="0 0 0"/>
      <geometry>
        <mesh filename="package://interbotix_uxarm_descriptions/meshes/uxarm5_meshes/uxarm5_link5.STL"/>
      </geometry>
    </collision>
    <inertial>
      <origin xyz="-3E-05 -0.00677 -0.01098" rpy="0 0 0" />
      <mass value="0.16" />
      <inertia ixx="9.341E-05" ixy="0" ixz="0" iyy="5.87E-05" iyz="3.57E-06" izz="1.33E-05"/>
    </inertial>
  </link>

  <xacro:if value="$(arg show_gripper)">
    <xacro:include filename="$(find interbotix_uxarm_descriptions)/urdf/uxarm_gripper.urdf.xacro"/>
  </xacro:if>

  <xacro:if value="${urdf_loc != ''}">
    <xacro:include filename="${urdf_loc}"/>
  </xacro:if>

</robot>
